Workbook

Sheet Info
A1: Data Transaksi Simulasi - Analisis Penjualan UMKM Kuliner
A2: Pengantar Data Sains | Studi Kasus 2 | Kelompok 6
A4: Keterangan umum
A5: Sumber data | B5: DATA SIMULASI, bukan transaksi nyata. Kesimpulan hanya berlaku untuk data ini.
A6: Periode | B6: 1-30 September 2026 (30 hari)
A7: Cara pembuatan | B7: Skrip Python buat_data_simulasi.py dengan seed acak 2026, berdasarkan parameter di bawah. Skrip disertakan agar data dapat dibuat ulang.
A8: Parameter simulasi | B8: 12 menu (7 makanan, 5 minuman); 40-52 transaksi per hari kerja dan 50-60 pada akhir pekan; 1-3 menu per transaksi; jam buka 08:00-20:59 dengan puncak siang (11-13) dan malam (18-19).
A9: Kesalahan sengaja | B9: Data_Mentah sengaja memuat kesalahan (kosong, duplikat, format jam, nama menu, harga, jumlah) untuk latihan pembersihan. Semua perubahan tercatat di Log_Pembersihan.
A10: Asumsi | B10: Harga jual tiap menu tetap selama periode (lihat Daftar_Menu). Satu ID transaksi dapat memuat beberapa baris menu.
A12: Ringkasan data (dihitung otomatis)
A13: Baris data mentah | B13: =COUNTA(Data_Mentah!A2:A2431) -> 2430
A14: Baris data bersih | B14: =COUNTA(Data_Bersih!A2:A2398) -> 2397
A15: Baris dikeluarkan | B15: =B13-B14 -> 33
A16: Jumlah transaksi (ID unik) | B16: =SUM(Data_Bersih!$L$2:$L$2398) -> 1433
A17: Total pendapatan (Rp) | B17: =SUM(Data_Bersih!$G$2:$G$2398) -> 38349000
A19: Ringkasan masalah data (dari Log_Pembersihan)
A20: Pencatatan ganda (duplikat) | B20: =COUNTIF(Log_Pembersihan!$D$2:$D$110,"Pencatatan ganda (duplikat)") -> 18
A21: Nama menu tidak seragam | B21: =COUNTIF(Log_Pembersihan!$D$2:$D$110,"Nama menu tidak seragam") -> 25
A22: Format jam tidak seragam | B22: =COUNTIF(Log_Pembersihan!$D$2:$D$110,"Format jam tidak seragam") -> 25
A23: Jam kosong | B23: =COUNTIF(Log_Pembersihan!$D$2:$D$110,"Jam kosong") -> 4
A24: Harga kosong | B24: =COUNTIF(Log_Pembersihan!$D$2:$D$110,"Harga kosong") -> 12
A25: Harga nol atau tidak wajar | B25: =COUNTIF(Log_Pembersihan!$D$2:$D$110,"Harga nol atau tidak wajar") -> 10
A26: Jumlah kosong | B26: =COUNTIF(Log_Pembersihan!$D$2:$D$110,"Jumlah kosong") -> 6
A27: Jumlah nol atau negatif | B27: =COUNTIF(Log_Pembersihan!$D$2:$D$110,"Jumlah nol atau negatif") -> 6
A28: Menu kosong | B28: =COUNTIF(Log_Pembersihan!$D$2:$D$110,"Menu kosong") -> 3
A29: Total temuan | B29: =SUM(B20:B28) -> 109
A31: Kamus data (sesuai Rencana Data, slide 8)
A32: Variabel | B32: Tipe Data | C32: Keterangan
A33: ID_Transaksi | B33: Kategorikal | C33: Kode unik tiap transaksi (untuk deteksi duplikat dan hitung transaksi)
A34: Tanggal | B34: Tanggal | C34: Hari terjadinya penjualan
A35: Menu | B35: Kategorikal | C35: Nama makanan atau minuman
A36: Jumlah | B36: Numerik | C36: Banyaknya produk yang terjual
A37: Jam | B37: Waktu | C37: Waktu terjadinya transaksi
A38: Harga | B38: Numerik | C38: Harga jual per unit produk (Rp)
A39: Total_Pendapatan | B39: Numerik turunan | C39: Jumlah x Harga (rumus per baris)
A40: Kategori | B40: Kategorikal turunan | C40: Makanan atau Minuman (dari Daftar_Menu)
A41: Hari | B41: Kategorikal turunan | C41: Hari dalam minggu dari Tanggal
A42: Jam_Bulat | B42: Numerik turunan | C42: Jam (0-23) dari Jam
A43: Kelompok_Jam | B43: Kategorikal turunan | C43: Pagi (<11), Siang (11-16), Malam (>=17)
A44: Transaksi_Baru | B44: Numerik turunan | C44: 1 pada baris pertama tiap ID transaksi (untuk menghitung jumlah transaksi)
...

Sheet Data_Mentah
A1: ID_Transaksi | B1: Tanggal | C1: Menu | D1: Jumlah | E1: Jam | F1: Harga
A2: TRX-0001 | B2: 46266 | C2: Soto Ayam | D2: 2 | E2: 10:57 | F2: 16000
A3: TRX-0001 | B3: 46266 | C3: Nasi Goreng | D3: 1 | E3: 10:57 | F3: 15000
A4: TRX-0001 | B4: 46266 | C4: Nasi Uduk | D4: 2 | E4: 10:57 | F4: 13000
A5: TRX-0002 | B5: 46266 | C5: Es Teh Manis | D5: 1 | E5: 11:03 | F5: 5000
A6: TRX-0003 | B6: 46266 | C6: Es Teh Manis | D6: 1 | E6: 12:06 | F6: 5000
A7: TRX-0004 | B7: 46266 | C7: Mie Goreng | D7: 1 | E7: 12:32 | F7: 14000
A8: TRX-0005 | B8: 46266 | C8: Teh Hangat | D8: 2 | E8: 12:35 | F8: 4000
A9: TRX-0005 | B9: 46266 | C9: Es Teh Manis | D9: 1 | E9: 12:35 | F9: 5000
A10: TRX-0006 | B10: 46266 | C10: Soto Ayam | D10: 1 | E10: 13:00 | F10: 16000
A11: TRX-0006 | B11: 46266 | C11: Es Teh Manis | D11: 1 | E11: 13:00 | F11: 5000
A12: TRX-0007 | B12: 46266 | C12: Nasi Goreng | D12: 1 | E12: 13:22 | F12: 15000
A13: TRX-0008 | B13: 46266 | C13: Soto Ayam | D13: 1 | E13: 13:24 | F13: 16000
... A77: TRX-0047 | B77: 46267 | C77: Kopi Susu | D77: 1 | E77: 11:44 | F77: 10000
A78: TRX-0047 | B78: 46267 | C78: Soto Ayam | D78: 2 | F78: 16000
A79: TRX-0048 | B79: 46267 | C79: Es Teh Manis | D79: 1 | E79: 11:44 | F79: 5000
A80: TRX-0048 | B80: 46267 | C80: Kopi Susu | D80: 1 | E80: 11:44 | F80: 10000
A81: TRX-0049 | B81: 46267 | C81: Nasi Goreng | D81: 1 | E81: 11:56 | F81: 15000
A82: TRX-0049 | B82: 46267 | C82: Nasi Ayam Bakar | D82: 2 | E82: 11:56 | F82: 20000
A83: TRX-0050 | B83: 46267 | C83: Es Jeruk | D83: 2 | E83: 11:58 | F83: 7000
A84: TRX-0051 | B84: 46267 | C84: Teh Hangat | D84: 1 | E84: 12:25 | F84: 4000
A85: TRX-0052 | B85: 46267 | C85: Nasi Uduk | D85: 3 | E85: 12:31 | F85: 13000
A86: TRX-0052 | B86: 46267 | C86: Kopi Susu | D86: 1 | E86: 12:31 | F86: 10000
A87: TRX-0053 | B87: 46267 | C87: Es Jeruk | D87: 2 | E87: 12:37 | F87: 7000
A88: TRX-0053 | B88: 46267 | C88: Air Mineral | D88: 1 | E88: 12:37 | F88: 3000
A89: TRX-0054 | B89: 46267 | C89: Nasi Ayam Bakar | D89: 1 | F89: 20000
A90: TRX-0054 | B90: 46267 | C90: Nasi Goreng | D90: 2 | E90: 12:39 | F90: 15000
A91: TRX-0054 | B91: 46267 | C91: Bakso | D91: 1 | E91: 12:39 | F91: 15000
A92: TRX-0055 | B92: 46267 | C92: Ayam Geprek | D92: 1 | E92: 12:56 | F92: 18000
A93: TRX-0056 | B93: 46267 | C93: Nasi Goreng | D93: 1 | E93: 12:59 | F93: 15000
A94: TRX-0056 | B94: 46267 | C94: Bakso | D94: 2 | E94: 12:59 | F94: 15000
A95: TRX-0057 | B95: 46267 | C95: Teh Hangat | D95: 1 | E95: 13:12 | F95: 4000
A96: TRX-0057 | B96: 46267 | C96: Es Teh Manis | D96: 3 | E96: 13:12 | F96: 5000
A97: TRX-0057 | B97: 46267 | C97: Nasi Ayam Bakar | D97: 1 | E97: 13:12 | F97: 20000
A98: TRX-0058 | B98: 46267 | C98: Es Teh Manis | D98: 1 | E98: 13:18:00 | F98: 5000
A99: TRX-0058 | B99: 46267 | C99: Bakso | D99: 3 | E99: 13:18 | F99: 15000
A100: TRX-0059 | B100: 46267 | C100: Nasi Ayam Bakar | D100: 1 | E100: 13:34 | F100: 20000
A101: TRX-0060 | B101: 46267 | C101: Nasi Goreng | D101: 1 | E101: 14:30 | F101: 15000
... A182: TRX-0108 | B182: 46268 | C182: Nasi Ayam Bakar | D182: 1 | E182: 15:50 | F182: 20000
A183: TRX-0109 | B183: 46268 | C183: Ayam Geprek | D183: 1 | E183: 15:55
...

Sheet Log_Pembersihan
A1: No | B1: Baris_di_Data_Mentah | C1: ID_Transaksi | D1: Masalah | E1: Nilai_Awal | F1: Tindakan | G1: Nilai_Akhir | H1: Langkah_Charter
A2: 1 | B2: 78 | C2: TRX-0047 | D2: Jam kosong | E2: (kosong) | F2: Diisi dari baris lain pada transaksi yang sama | G2: 11:44 | H2: Langkah 5
A3: 2 | B3: 89 | C3: TRX-0054 | D3: Jam kosong | E3: (kosong) | F3: Diisi dari baris lain pada transaksi yang sama | G3: 12:39 | H3: Langkah 5
A4: 3 | B4: 98 | C4: TRX-0058 | D4: Format jam tidak seragam | E4: 13:18:00 | F4: Diseragamkan ke HH:MM | G4: 13:18 | H4: Langkah 3
A5: 4 | B5: 138 | C5: TRX-0084 | D5: Nama menu tidak seragam | E5: 'MIE GORENG' | F5: Diseragamkan ke nama baku | G5: Mie Goreng | H5: Langkah 3
A6: 5 | B6: 183 | C6: TRX-0109 | D6: Harga kosong | E6: (kosong) | F6: Diisi dari harga baku menu | G6: 18.000 | H6: Langkah 5
A7: 6 | B7: 191 | C7: TRX-0113 | D7: Harga kosong | E7: (kosong) | F7: Diisi dari harga baku menu | G7: 18.000 | H7: Langkah 5
A8: 7 | B8: 198 | C8: TRX-0116 | D8: Format jam tidak seragam | E8: 17:30 WIB | F8: Diseragamkan ke HH:MM | G8: 17:30 | H8: Langkah 3
A9: 8 | B9: 222 | C9: TRX-0132 | D9: Nama menu tidak seragam | E9: 'Soto Ayam ' | F9: Diseragamkan ke nama baku | G9: Soto Ayam | H9: Langkah 3
A10: 9 | B10: 235 | C10: TRX-0140 | D10: Jam kosong | E10: (kosong) | F10: Diisi dari baris lain pada transaksi yang sama | G10: 11:50 | H10: Langkah 5
A11: 10 | B11: 240 | C11: TRX-0144 | D11: Menu kosong | E11: (kosong) | F11: Dihapus: menu tidak dapat dipulihkan | G11: (baris dikeluarkan) | H11: Langkah 5
A12: 11 | B12: 283 | C12: TRX-0170 | D12: Nama menu tidak seragam | E12: 'NASI GORENG' | F12: Diseragamkan ke nama baku | G12: Nasi Goreng | H12: Langkah 3
A13: 12 | B13: 291 | C13: TRX-0175 | D13: Nama menu tidak seragam | E13: 'Nasi Uduk' | F13: Diseragamkan ke nama baku | G13: Nasi Uduk | H13: Langkah 3
... A110: 109 | B110: 2422 | C110: TRX-1434 | D110: Pencatatan ganda (duplikat) | E110: Mie Goreng | 1 | 19:19 | F110: Dihapus (baris pertama dipertahankan) | G110: (baris dikeluarkan) | H110: Langkah 2

Sheet Data_Bersih
A1: ID_Transaksi | B1: Tanggal | C1: Menu | D1: Jumlah | E1: Jam | F1: Harga | G1: Total_Pendapatan | H1: Kategori | I1: Hari | J1: Jam_Bulat | K1: Kelompok_Jam | L1: Transaksi_Baru
A2: TRX-0001 | B2: 46266 | C2: Soto Ayam | D2: 2 | E2: 0.45625 | F2: 16000 | G2: =D2*F2 -> 32000 | H2: =INDEX(Daftar_Menu!$B$2:$B$13,MATCH(C2,Daftar_Menu!$A$2:$A$13,0)) -> Makanan | I2: =CHOOSE(WEEKDAY(B2,2),"Senin","Selasa","Rabu","Kamis","Jumat","Sabtu","Minggu") -> Selasa | J2: =HOUR(E2) -> 10 | K2: =IF(J2<11,"Pagi",IF(J2<17,"Siang","Malam")) -> Pagi | L2: =IF(A2<>A1,1,0) -> 1
A3: TRX-0001 | B3: 46266 | C3: Nasi Goreng | D3: 1 | E3: 0.45625 | F3: 15000 | G3: =D3*F3 -> 15000 | H3: =INDEX(Daftar_Menu!$B$2:$B$13,MATCH(C3,Daftar_Menu!$A$2:$A$13,0)) -> Makanan | I3: =CHOOSE(WEEKDAY(B3,2),"Senin","Selasa","Rabu","Kamis","Jumat","Sabtu","Minggu") -> Selasa | J3: =HOUR(E3) -> 10 | K3: =IF(J3<11,"Pagi",IF(J3<17,"Siang","Malam")) -> Pagi | L3: =IF(A3<>A2,1,0) -> 0
A4: TRX-0001 | B4: 46266 | C4: Nasi Uduk | D4: 2 | E4: 0.45625 | F4: 13000 | G4: =D4*F4 -> 26000 | H4: =INDEX(Daftar_Menu!$B$2:$B$13,MATCH(C4,Daftar_Menu!$A$2:$A$13,0)) -> Makanan | I4: =CHOOSE(WEEKDAY(B4,2),"Senin","Selasa","Rabu","Kamis","Jumat","Sabtu","Minggu") -> Selasa | J4: =HOUR(E4) -> 10 | K4: =IF(J4<11,"Pagi",IF(J4<17,"Siang","Malam")) -> Pagi | L4: =IF(A4<>A3,1,0) -> 0
A5: TRX-0002 | B5: 46266 | C5: Es Teh Manis | D5: 1 | E5: 0.46041667 | F5: 5000 | G5: =D5*F5 -> 5000 | H5: =INDEX(Daftar_Menu!$B$2:$B$13,MATCH(C5,Daftar_Menu!$A$2:$A$13,0)) -> Minuman | I5: =CHOOSE(WEEKDAY(B5,2),"Senin","Selasa","Rabu","Kamis","Jumat","Sabtu","Minggu") -> Selasa | J5: =HOUR(E5) -> 11 | K5: =IF(J5<11,"Pagi",IF(J5<17,"Siang","Malam")) -> Siang | L5: =IF(A5<>A4,1,0) -> 1
A6: TRX-0003 | B6: 46266 | C6: Es Teh Manis | D6: 1 | E6: 0.50416667 | F6: 5000 | G6: =D6*F6 -> 5000 | H6: =INDEX(Daftar_Menu!$B$2:$B$13,MATCH(C6,Daftar_Menu!$A$2:$A$13,0)) -> Minuman | I6: =CHOOSE(WEEKDAY(B6,2),"Senin","Selasa","Rabu","Kamis","Jumat","Sabtu","Minggu") -> Selasa | J6: =HOUR(E6) -> 12 | K6: =IF(J6<11,"Pagi",IF(J6<17,"Siang","Malam")) -> Siang | L6: =IF(A6<>A5,1,0) -> 1
A7: TRX-0004 | B7: 46266 | C7: Mie Goreng | D7: 1 | E7: 0.52222222 | F7: 14000 | G7: =D7*F7 -> 14000 | H7: =INDEX(Daftar_Menu!$B$2:$B$13,MATCH(C7,Daftar_Menu!$A$2:$A$13,0)) -> Makanan | I7: =CHOOSE(WEEKDAY(B7,2),"Senin","Selasa","Rabu","Kamis","Jumat","Sabtu","Minggu") -> Selasa | J7: =HOUR(E7) -> 12 | K7: =IF(J7<11,"Pagi",IF(J7<17,"Siang","Malam")) -> Siang | L7: =IF(A7<>A6,1,0) -> 1
A8: TRX-0005 | B8: 46266 | C8: Teh Hangat | D8: 2 | E8: 0.52430556 | F8: 4000 | G8: =D8*F8 -> 8000 | H8: =INDEX(Daftar_Menu!$B$2:$B$13,MATCH(C8,Daftar_Menu!$A$2:$A$13,0)) -> Minuman | I8: =CHOOSE(WEEKDAY(B8,2),"Senin","Selasa","Rabu","Kamis","Jumat","Sabtu","Minggu") -> Selasa | J8: =HOUR(E8) -> 12 | K8: =IF(J8<11,"Pagi",IF(J8<17,"Siang","Malam")) -> Siang | L8: =IF(A8<>A7,1,0) -> 1
A9: TRX-0005 | B9: 46266 | C9: Es Teh Manis | D9: 1 | E9: 0.52430556 | F9: 5000 | G9: =D9*F9 -> 5000 | H9: =INDEX(Daftar_Menu!$B$2:$B$13,MATCH(C9,Daftar_Menu!$A$2:$A$13,0)) -> Minuman | I9: =CHOOSE(WEEKDAY(B9,2),"Senin","Selasa","Rabu","Kamis","Jumat","Sabtu","Minggu") -> Selasa | J9: =HOUR(E9) -> 12 | K9: =IF(J9<11,"Pagi",IF(J9<17,"Siang","Malam")) -> Siang | L9: =IF(A9<>A8,1,0) -> 0
A10: TRX-0006 | B10: 46266 | C10: Soto Ayam | D10: 1 | E10: 0.54166667 | F10: 16000 | G10: =D10*F10 -> 16000 | H10: =INDEX(Daftar_Menu!$B$2:$B$13,MATCH(C10,Daftar_Menu!$A$2:$A$13,0)) -> Makanan | I10: =CHOOSE(WEEKDAY(B10,2),"Senin","Selasa","Rabu","Kamis","Jumat","Sabtu","Minggu") -> Selasa | J10: =HOUR(E10) -> 13 | K10: =IF(J10<11,"Pagi",IF(J10<17,"Siang","Malam")) -> Siang | L10: =IF(A10<>A9,1,0) -> 1
A11: TRX-0006 | B11: 46266 | C11: Es Teh Manis | D11: 1 | E11: 0.54166667 | F11: 5000 | G11: =D11*F11 -> 5000 | H11: =INDEX(Daftar_Menu!$B$2:$B$13,MATCH(C11,Daftar_Menu!$A$2:$A$13,0)) -> Minuman | I11: =CHOOSE(WEEKDAY(B11,2),"Senin","Selasa","Rabu","Kamis","Jumat","Sabtu","Minggu") -> Selasa | J11: =HOUR(E11) -> 13 | K11: =IF(J11<11,"Pagi",IF(J11<17,"Siang","Malam")) -> Siang | L11: =IF(A11<>A10,1,0) -> 0
A12: TRX-0007 | B12: 46266 | C12: Nasi Goreng | D12: 1 | E12: 0.55694444 | F12: 15000 | G12: =D12*F12 -> 15000 | H12: =INDEX(Daftar_Menu!$B$2:$B$13,MATCH(C12,Daftar_Menu!$A$2:$A$13,0)) -> Makanan | I12: =CHOOSE(WEEKDAY(B12,2),"Senin","Selasa","Rabu","Kamis","Jumat","Sabtu","Minggu") -> Selasa | J12: =HOUR(E12) -> 13 | K12: =IF(J12<11,"Pagi",IF(J12<17,"Siang","Malam")) -> Siang | L12: =IF(A12<>A11,1,0) -> 1
A13: TRX-0008 | B13: 46266 | C13: Soto Ayam | D13: 1 | E13: 0.55833333 | F13: 16000 | G13: =D13*F13 -> 16000 | H13: =INDEX(Daftar_Menu!$B$2:$B$13,MATCH(C13,Daftar_Menu!$A$2:$A$13,0)) -> Makanan | I13: =CHOOSE(WEEKDAY(B13,2),"Senin","Selasa","Rabu","Kamis","Jumat","Sabtu","Minggu") -> Selasa | J13: =HOUR(E13) -> 13 | K13: =IF(J13<11,"Pagi",IF(J13<17,"Siang","Malam")) -> Siang | L13: =IF(A13<>A12,1,0) -> 1
... A2398: TRX-1438 | B2398: 46295 | C2398: Es Teh Manis | D2398: 1 | E2398: 0.82361111 | F2398: 5000 | G2398: =D2398*F2398 -> 5000 | H2398: =INDEX(Daftar_Menu!$B$2:$B$13,MATCH(C2398,Daftar_Menu!$A$2:$A$13,0)) -> Minuman | I2398: =CHOOSE(WEEKDAY(B2398,2),"Senin","Selasa","Rabu","Kamis","Jumat","Sabtu","Minggu") -> Rabu | J2398: =HOUR(E2398) -> 19 | K2398: =IF(J2398<11,"Pagi",IF(J2398<17,"Siang","Malam")) -> Malam | L2398: =IF(A2398<>A2397,1,0) -> 0

Sheet Ringkasan_Menu
A1: Menu | B1: Kategori | C1: Jumlah_Terjual | D1: Total_Pendapatan (Rp) | E1: Kontribusi_Pendapatan | F1: Peringkat_Terjual | G1: Peringkat_Pendapatan
A2: =Daftar_Menu!A2 -> Nasi Goreng | B2: =Daftar_Menu!B2 -> Makanan | C2: =SUMIFS(Data_Bersih!$D$2:$D$2398,Data_Bersih!$C$2:$C$2398,A2) -> 432 | D2: =SUMIFS(Data_Bersih!$G$2:$G$2398,Data_Bersih!$C$2:$C$2398,A2) -> 6480000 | E2: =D2/$D$14 -> 0.16897442 | F2: =RANK(C2,$C$2:$C$13) -> 2 | G2: =RANK(D2,$D$2:$D$13) -> 2
A3: =Daftar_Menu!A3 -> Mie Goreng | B3: =Daftar_Menu!B3 -> Makanan | C3: =SUMIFS(Data_Bersih!$D$2:$D$2398,Data_Bersih!$C$2:$C$2398,A3) -> 278 | D3: =SUMIFS(Data_Bersih!$G$2:$G$2398,Data_Bersih!$C$2:$C$2398,A3) -> 3892000 | E3: =D3/$D$14 -> 0.10148896 | F3: =RANK(C3,$C$2:$C$13) -> 5 | G3: =RANK(D3,$D$2:$D$13) -> 5
A4: =Daftar_Menu!A4 -> Ayam Geprek | B4: =Daftar_Menu!B4 -> Makanan | C4: =SUMIFS(Data_Bersih!$D$2:$D$2398,Data_Bersih!$C$2:$C$2398,A4) -> 371 | D4: =SUMIFS(Data_Bersih!$G$2:$G$2398,Data_Bersih!$C$2:$C$2398,A4) -> 6678000 | E4: =D4/$D$14 -> 0.17413753 | F4: =RANK(C4,$C$2:$C$13) -> 3 | G4: =RANK(D4,$D$2:$D$13) -> 1
A5: =Daftar_Menu!A5 -> Nasi Ayam Bakar | B5: =Daftar_Menu!B5 -> Makanan | C5: =SUMIFS(Data_Bersih!$D$2:$D$2398,Data_Bersih!$C$2:$C$2398,A5) -> 219 | D5: =SUMIFS(Data_Bersih!$G$2:$G$2398,Data_Bersih!$C$2:$C$2398,A5) -> 4380000 | E5: =D5/$D$14 -> 0.11421419 | F5: =RANK(C5,$C$2:$C$13) -> 8 | G5: =RANK(D5,$D$2:$D$13) -> 3
A6: =Daftar_Menu!A6 -> Soto Ayam | B6: =Daftar_Menu!B6 -> Makanan | C6: =SUMIFS(Data_Bersih!$D$2:$D$2398,Data_Bersih!$C$2:$C$2398,A6) -> 227 | D6: =SUMIFS(Data_Bersih!$G$2:$G$2398,Data_Bersih!$C$2:$C$2398,A6) -> 3632000 | E6: =D6/$D$14 -> 0.094709119 | F6: =RANK(C6,$C$2:$C$13) -> 7 | G6: =RANK(D6,$D$2:$D$13) -> 6
A7: =Daftar_Menu!A7 -> Bakso | B7: =Daftar_Menu!B7 -> Makanan | C7: =SUMIFS(Data_Bersih!$D$2:$D$2398,Data_Bersih!$C$2:$C$2398,A7) -> 280 | D7: =SUMIFS(Data_Bersih!$G$2:$G$2398,Data_Bersih!$C$2:$C$2398,A7) -> 4200000 | E7: =D7/$D$14 -> 0.10952046 | F7: =RANK(C7,$C$2:$C$13) -> 4 | G7: =RANK(D7,$D$2:$D$13) -> 4
A8: =Daftar_Menu!A8 -> Nasi Uduk | B8: =Daftar_Menu!B8 -> Makanan | C8: =SUMIFS(Data_Bersih!$D$2:$D$2398,Data_Bersih!$C$2:$C$2398,A8) -> 115 | D8: =SUMIFS(Data_Bersih!$G$2:$G$2398,Data_Bersih!$C$2:$C$2398,A8) -> 1495000 | E8: =D8/$D$14 -> 0.038984067 | F8: =RANK(C8,$C$2:$C$13) -> 11 | G8: =RANK(D8,$D$2:$D$13) -> 10
A9: =Daftar_Menu!A9 -> Es Teh Manis | B9: =Daftar_Menu!B9 -> Minuman | C9: =SUMIFS(Data_Bersih!$D$2:$D$2398,Data_Bersih!$C$2:$C$2398,A9) -> 543 | D9: =SUMIFS(Data_Bersih!$G$2:$G$2398,Data_Bersih!$C$2:$C$2398,A9) -> 2715000 | E9: =D9/$D$14 -> 0.070797152 | F9: =RANK(C9,$C$2:$C$13) -> 1 | G9: =RANK(D9,$D$2:$D$13) -> 7
A10: =Daftar_Menu!A10 -> Teh Hangat | B10: =Daftar_Menu!B10 -> Minuman | C10: =SUMIFS(Data_Bersih!$D$2:$D$2398,Data_Bersih!$C$2:$C$2398,A10) -> 145 | D10: =SUMIFS(Data_Bersih!$G$2:$G$2398,Data_Bersih!$C$2:$C$2398,A10) -> 580000 | E10: =D10/$D$14 -> 0.015124254 | F10: =RANK(C10,$C$2:$C$13) -> 10 | G10: =RANK(D10,$D$2:$D$13) -> 11
A11: =Daftar_Menu!A11 -> Es Jeruk | B11: =Daftar_Menu!B11 -> Minuman | C11: =SUMIFS(Data_Bersih!$D$2:$D$2398,Data_Bersih!$C$2:$C$2398,A11) -> 255 | D11: =SUMIFS(Data_Bersih!$G$2:$G$2398,Data_Bersih!$C$2:$C$2398,A11) -> 1785000 | E11: =D11/$D$14 -> 0.046546194 | F11: =RANK(C11,$C$2:$C$13) -> 6 | G11: =RANK(D11,$D$2:$D$13) -> 9
A12: =Daftar_Menu!A12 -> Kopi Susu | B12: =Daftar_Menu!B12 -> Minuman | C12: =SUMIFS(Data_Bersih!$D$2:$D$2398,Data_Bersih!$C$2:$C$2398,A12) -> 217 | D12: =SUMIFS(Data_Bersih!$G$2:$G$2398,Data_Bersih!$C$2:$C$2398,A12) -> 2170000 | E12: =D12/$D$14 -> 0.056585569 | F12: =RANK(C12,$C$2:$C$13) -> 9 | G12: =RANK(D12,$D$2:$D$13) -> 8
A13: =Daftar_Menu!A13 -> Air Mineral | B13: =Daftar_Menu!B13 -> Minuman | C13: =SUMIFS(Data_Bersih!$D$2:$D$2398,Data_Bersih!$C$2:$C$2398,A13) -> 114 | D13: =SUMIFS(Data_Bersih!$G$2:$G$2398,Data_Bersih!$C$2:$C$2398,A13) -> 342000 | E13: =D13/$D$14 -> 0.0089180943 | F13: =RANK(C13,$C$2:$C$13) -> 12 | G13: =RANK(D13,$D$2:$D$13) -> 12
A14: TOTAL | C14: =SUM(C2:C13) -> 3196 | D14: =SUM(D2:D13) -> 38349000 | E14: =SUM(E2:E13) -> 1
A16: Cek konsistensi: total ringkasan - total Data_Bersih (harus 0) | D16: =D14-SUM(Data_Bersih!$G$2:$G$2398) -> 0
A18: Catatan: tabel ini dihitung dengan rumus dari Data_Bersih. Angkanya hanya berlaku untuk data simulasi ini.

Sheet Ringkasan_Jam
A1: Jam | B1: Jam_Bulat | C1: Jumlah_Transaksi | D1: Jumlah_Item_Terjual | E1: Total_Pendapatan (Rp) | F1: Peringkat_Pendapatan | G1: Peringkat_Transaksi
A2: 08:00-08:59 | B2: 8 | C2: =SUMIFS(Data_Bersih!$L$2:$L$2398,Data_Bersih!$J$2:$J$2398,B2) -> 33 | D2: =SUMIFS(Data_Bersih!$D$2:$D$2398,Data_Bersih!$J$2:$J$2398,B2) -> 77 | E2: =SUMIFS(Data_Bersih!$G$2:$G$2398,Data_Bersih!$J$2:$J$2398,B2) -> 970000 | F2: =RANK(E2,$E$2:$E$14) -> 13 | G2: =RANK(C2,$C$2:$C$14) -> 13
A3: 09:00-09:59 | B3: 9 | C3: =SUMIFS(Data_Bersih!$L$2:$L$2398,Data_Bersih!$J$2:$J$2398,B3) -> 55 | D3: =SUMIFS(Data_Bersih!$D$2:$D$2398,Data_Bersih!$J$2:$J$2398,B3) -> 118 | E3: =SUMIFS(Data_Bersih!$G$2:$G$2398,Data_Bersih!$J$2:$J$2398,B3) -> 1330000 | F3: =RANK(E3,$E$2:$E$14) -> 12 | G3: =RANK(C3,$C$2:$C$14) -> 11
A4: 10:00-10:59 | B4: 10 | C4: =SUMIFS(Data_Bersih!$L$2:$L$2398,Data_Bersih!$J$2:$J$2398,B4) -> 55 | D4: =SUMIFS(Data_Bersih!$D$2:$D$2398,Data_Bersih!$J$2:$J$2398,B4) -> 114 | E4: =SUMIFS(Data_Bersih!$G$2:$G$2398,Data_Bersih!$J$2:$J$2398,B4) -> 1403000 | F4: =RANK(E4,$E$2:$E$14) -> 11 | G4: =RANK(C4,$C$2:$C$14) -> 11
A5: 11:00-11:59 | B5: 11 | C5: =SUMIFS(Data_Bersih!$L$2:$L$2398,Data_Bersih!$J$2:$J$2398,B5) -> 143 | D5: =SUMIFS(Data_Bersih!$D$2:$D$2398,Data_Bersih!$J$2:$J$2398,B5) -> 323 | E5: =SUMIFS(Data_Bersih!$G$2:$G$2398,Data_Bersih!$J$2:$J$2398,B5) -> 3711000 | F5: =RANK(E5,$E$2:$E$14) -> 4 | G5: =RANK(C5,$C$2:$C$14) -> 5
A6: 12:00-12:59 | B6: 12 | C6: =SUMIFS(Data_Bersih!$L$2:$L$2398,Data_Bersih!$J$2:$J$2398,B6) -> 212 | D6: =SUMIFS(Data_Bersih!$D$2:$D$2398,Data_Bersih!$J$2:$J$2398,B6) -> 478 | E6: =SUMIFS(Data_Bersih!$G$2:$G$2398,Data_Bersih!$J$2:$J$2398,B6) -> 5928000 | F6: =RANK(E6,$E$2:$E$14) -> 1 | G6: =RANK(C6,$C$2:$C$14) -> 1
A7: 13:00-13:59 | B7: 13 | C7: =SUMIFS(Data_Bersih!$L$2:$L$2398,Data_Bersih!$J$2:$J$2398,B7) -> 148 | D7: =SUMIFS(Data_Bersih!$D$2:$D$2398,Data_Bersih!$J$2:$J$2398,B7) -> 304 | E7: =SUMIFS(Data_Bersih!$G$2:$G$2398,Data_Bersih!$J$2:$J$2398,B7) -> 3555000 | F7: =RANK(E7,$E$2:$E$14) -> 5 | G7: =RANK(C7,$C$2:$C$14) -> 4
A8: 14:00-14:59 | B8: 14 | C8: =SUMIFS(Data_Bersih!$L$2:$L$2398,Data_Bersih!$J$2:$J$2398,B8) -> 70 | D8: =SUMIFS(Data_Bersih!$D$2:$D$2398,Data_Bersih!$J$2:$J$2398,B8) -> 154 | E8: =SUMIFS(Data_Bersih!$G$2:$G$2398,Data_Bersih!$J$2:$J$2398,B8) -> 1865000 | F8: =RANK(E8,$E$2:$E$14) -> 10 | G8: =RANK(C8,$C$2:$C$14) -> 8
A9: 15:00-15:59 | B9: 15 | C9: =SUMIFS(Data_Bersih!$L$2:$L$2398,Data_Bersih!$J$2:$J$2398,B9) -> 67 | D9: =SUMIFS(Data_Bersih!$D$2:$D$2398,Data_Bersih!$J$2:$J$2398,B9) -> 152 | E9: =SUMIFS(Data_Bersih!$G$2:$G$2398,Data_Bersih!$J$2:$J$2398,B9) -> 1914000 | F9: =RANK(E9,$E$2:$E$14) -> 8 | G9: =RANK(C9,$C$2:$C$14) -> 10
A10: 16:00-16:59 | B10: 16 | C10: =SUMIFS(Data_Bersih!$L$2:$L$2398,Data_Bersih!$J$2:$J$2398,B10) -> 70 | D10: =SUMIFS(Data_Bersih!$D$2:$D$2398,Data_Bersih!$J$2:$J$2398,B10) -> 149 | E10: =SUMIFS(Data_Bersih!$G$2:$G$2398,Data_Bersih!$J$2:$J$2398,B10) -> 1874000 | F10: =RANK(E10,$E$2:$E$14) -> 9 | G10: =RANK(C10,$C$2:$C$14) -> 8
A11: 17:00-17:59 | B11: 17 | C11: =SUMIFS(Data_Bersih!$L$2:$L$2398,Data_Bersih!$J$2:$J$2398,B11) -> 123 | D11: =SUMIFS(Data_Bersih!$D$2:$D$2398,Data_Bersih!$J$2:$J$2398,B11) -> 269 | E11: =SUMIFS(Data_Bersih!$G$2:$G$2398,Data_Bersih!$J$2:$J$2398,B11) -> 3279000 | F11: =RANK(E11,$E$2:$E$14) -> 6 | G11: =RANK(C11,$C$2:$C$14) -> 6
A12: 18:00-18:59 | B12: 18 | C12: =SUMIFS(Data_Bersih!$L$2:$L$2398,Data_Bersih!$J$2:$J$2398,B12) -> 190 | D12: =SUMIFS(Data_Bersih!$D$2:$D$2398,Data_Bersih!$J$2:$J$2398,B12) -> 429 | E12: =SUMIFS(Data_Bersih!$G$2:$G$2398,Data_Bersih!$J$2:$J$2398,B12) -> 5166000 | F12: =RANK(E12,$E$2:$E$14) -> 2 | G12: =RANK(C12,$C$2:$C$14) -> 2
A13: 19:00-19:59 | B13: 19 | C13: =SUMIFS(Data_Bersih!$L$2:$L$2398,Data_Bersih!$J$2:$J$2398,B13) -> 172 | D13: =SUMIFS(Data_Bersih!$D$2:$D$2398,Data_Bersih!$J$2:$J$2398,B13) -> 417 | E13: =SUMIFS(Data_Bersih!$G$2:$G$2398,Data_Bersih!$J$2:$J$2398,B13) -> 4926000 | F13: =RANK(E13,$E$2:$E$14) -> 3 | G13: =RANK(C13,$C$2:$C$14) -> 3
A14: 20:00-20:59 | B14: 20 | C14: =SUMIFS(Data_Bersih!$L$2:$L$2398,Data_Bersih!$J$2:$J$2398,B14) -> 95 | D14: =SUMIFS(Data_Bersih!$D$2:$D$2398,Data_Bersih!$J$2:$J$2398,B14) -> 212 | E14: =SUMIFS(Data_Bersih!$G$2:$G$2398,Data_Bersih!$J$2:$J$2398,B14) -> 2428000 | F14: =RANK(E14,$E$2:$E$14) -> 7 | G14: =RANK(C14,$C$2:$C$14) -> 7
A15: TOTAL | C15: =SUM(C2:C14) -> 1433 | D15: =SUM(D2:D14) -> 3196 | E15: =SUM(E2:E14) -> 38349000
A17: Cek konsistensi: total pendapatan per jam - total Data_Bersih (harus 0) | E17: =E15-SUM(Data_Bersih!$G$2:$G$2398) -> 0
A19: Catatan: Jumlah_Transaksi = jumlah ID transaksi unik pada jam tersebut (kolom Transaksi_Baru).

Sheet Daftar_Menu
A1: Menu | B1: Kategori | C1: Harga_Baku (Rp) | D1: Alias_Penulisan_Dikenali
A2: Nasi Goreng | B2: Makanan | C2: 15000 | D2: -
A3: Mie Goreng | B3: Makanan | C3: 14000 | D3: -
A4: Ayam Geprek | B4: Makanan | C4: 18000 | D4: -
A5: Nasi Ayam Bakar | B5: Makanan | C5: 20000 | D5: Ayam Bakar
A6: Soto Ayam | B6: Makanan | C6: 16000 | D6: -
A7: Bakso | B7: Makanan | C7: 15000 | D7: -
A8: Nasi Uduk | B8: Makanan | C8: 13000 | D8: -
A9: Es Teh Manis | B9: Minuman | C9: 5000 | D9: Es Teh
A10: Teh Hangat | B10: Minuman | C10: 4000 | D10: -
A11: Es Jeruk | B11: Minuman | C11: 7000 | D11: -
A12: Kopi Susu | B12: Minuman | C12: 10000 | D12: -
A13: Air Mineral | B13: Minuman | C13: 3000 | D13: -
A15: Catatan: harga baku (biru) adalah masukan simulasi dan dianggap tetap selama 30 hari. Dipakai untuk mengisi/mengoreksi harga saat pembersihan.
